<sdf version='1.7'>
  <world name='default'>
    <light name='sun' type='directional'>
      <cast_shadows>1</cast_shadows>
      <pose>0 0 10 0 -0 0</pose>
      <diffuse>0.8 0.8 0.8 1</diffuse>
      <specular>0.2 0.2 0.2 1</specular>
      <attenuation>
        <range>1000</range>
        <constant>0.9</constant>
        <linear>0.01</linear>
        <quadratic>0.001</quadratic>
      </attenuation>
      <direction>-0.5 0.1 -0.9</direction>
      <spot>
        <inner_angle>0</inner_angle>
        <outer_angle>0</outer_angle>
        <falloff>0</falloff>
      </spot>
    </light>
    <model name='ground_plane'>
      <static>1</static>
      <link name='link'>
        <collision name='collision'>
          <geometry>
            <plane>
              <normal>0 0 1</normal>
              <size>100 100</size>
            </plane>
          </geometry>
          <surface>
            <friction>
              <ode>
                <mu>100</mu>
                <mu2>50</mu2>
              </ode>
              <torsional>
                <ode/>
              </torsional>
            </friction>
            <contact>
              <ode/>
            </contact>
            <bounce/>
          </surface>
          <max_contacts>10</max_contacts>
        </collision>
        <visual name='visual'>
          <cast_shadows>0</cast_shadows>
          <geometry>
            <plane>
              <normal>0 0 1</normal>
              <size>100 100</size>
            </plane>
          </geometry>
          <material>
            <script>
              <uri>file://media/materials/scripts/gazebo.material</uri>
              <name>Gazebo/Grey</name>
            </script>
          </material>
        </visual>
        <self_collide>0</self_collide>
        <enable_wind>0</enable_wind>
        <kinematic>0</kinematic>
      </link>
    </model>
    <gravity>0 0 -9.8</gravity>
    <magnetic_field>6e-06 2.3e-05 -4.2e-05</magnetic_field>
    <atmosphere type='adiabatic'/>
    <physics type='ode'>
      <max_step_size>0.001</max_step_size>
      <real_time_factor>1</real_time_factor>
      <real_time_update_rate>1000</real_time_update_rate>
    </physics>
    <scene>
      <ambient>0.4 0.4 0.4 1</ambient>
      <background>0.7 0.7 0.7 1</background>
      <shadows>1</shadows>
    </scene>
    <audio>
      <device>default</device>
    </audio>
    <wind/>
    <spherical_coordinates>
      <surface_model>EARTH_WGS84</surface_model>
      <latitude_deg>0</latitude_deg>
      <longitude_deg>0</longitude_deg>
      <elevation>0</elevation>
      <heading_deg>0</heading_deg>
    </spherical_coordinates>
    <model name='my_bot'>
      <link name='base_link'>
        <inertial>
          <pose>-0.067475 0 0.081098 0 -0 0</pose>
          <mass>0.61</mass>
          <inertia>
            <ixx>0.00561003</ixx>
            <ixy>0</ixy>
            <ixz>0.000453811</ixz>
            <iyy>0.00760348</iyy>
            <iyz>0</iyz>
            <izz>0.00797093</izz>
          </inertia>
        </inertial>
        <collision name='base_link_fixed_joint_lump__chassis_collision'>
          <pose>-0.0585 0 0.059 0 -0 0</pose>
          <geometry>
            <box>
              <size>0.335 0.265 0.138</size>
            </box>
          </geometry>
          <surface>
            <contact>
              <ode/>
            </contact>
            <friction>
              <ode/>
              <torsional>
                <ode/>
              </torsional>
            </friction>
            <bounce/>
          </surface>
          <max_contacts>10</max_contacts>
        </collision>
        <collision name='base_link_fixed_joint_lump__caster_wheel_collision_1'>
          <pose>-0.151 0 -0.023 0 -0 0</pose>
          <geometry>
            <sphere>
              <radius>0.01</radius>
            </sphere>
          </geometry>
          <surface>
            <contact>
              <ode/>
            </contact>
            <friction>
              <ode>
                <mu>0.001</mu>
                <mu2>0.001</mu2>
              </ode>
              <torsional>
                <ode/>
              </torsional>
            </friction>
            <bounce/>
          </surface>
          <max_contacts>10</max_contacts>
        </collision>
        <collision name='base_link_fixed_joint_lump__laser_frame_collision_2'>
          <pose>-0.104 0 0.202 0 -0 0</pose>
          <geometry>
            <cylinder>
              <length>0.04</length>
              <radius>0.05</radius>
            </cylinder>
          </geometry>
          <surface>
            <contact>
              <ode/>
            </contact>
            <friction>
              <ode/>
              <torsional>
                <ode/>
              </torsional>
            </friction>
            <bounce/>
          </surface>
          <max_contacts>10</max_contacts>
        </collision>
        <visual name='base_link_fixed_joint_lump__chassis_visual'>
          <pose>-0.0585 0 0.059 0 -0 0</pose>
          <geometry>
            <box>
              <size>0.335 0.265 0.138</size>
            </box>
          </geometry>
          <material>
            <script>
              <name>Gazebo/Orange</name>
              <uri>file://media/materials/scripts/gazebo.material</uri>
            </script>
          </material>
        </visual>
        <visual name='base_link_fixed_joint_lump__camera_link_visual_1'>
          <pose>0.05 0 0.171 0 -0 0</pose>
          <geometry>
            <box>
              <size>0.01 0.03 0.03</size>
            </box>
          </geometry>
          <material>
            <script>
              <name>Gazebo/Black</name>
              <uri>file://media/materials/scripts/gazebo.material</uri>
            </script>
          </material>
        </visual>
        <visual name='base_link_fixed_joint_lump__camera_link_visual_2'>
          <pose>0.05 0 0.121 0 -0 0</pose>
          <geometry>
            <cylinder>
              <length>0.1</length>
              <radius>0.002</radius>
            </cylinder>
          </geometry>
          <material>
            <script>
              <name>Gazebo/Black</name>
              <uri>file://media/materials/scripts/gazebo.material</uri>
            </script>
          </material>
        </visual>
        <visual name='base_link_fixed_joint_lump__caster_wheel_visual_3'>
          <pose>-0.151 0 -0.023 0 -0 0</pose>
          <geometry>
            <sphere>
              <radius>0.01</radius>
            </sphere>
          </geometry>
          <material>
            <script>
              <name>Gazebo/White</name>
              <uri>file://media/materials/scripts/gazebo.material</uri>
            </script>
          </material>
        </visual>
        <visual name='base_link_fixed_joint_lump__face_link_visual_4'>
          <pose>0.109 0.05 0.069 3.14159 1.57079 3.14159</pose>
          <geometry>
            <cylinder>
              <length>0.002</length>
              <radius>0.01</radius>
            </cylinder>
          </geometry>
          <material>
            <script>
              <name>Gazebo/Black</name>
              <uri>file://media/materials/scripts/gazebo.material</uri>
            </script>
          </material>
        </visual>
        <visual name='base_link_fixed_joint_lump__face_link_visual_5'>
          <pose>0.109 -0.05 0.069 3.14159 1.57079 3.14159</pose>
          <geometry>
            <cylinder>
              <length>0.002</length>
              <radius>0.01</radius>
            </cylinder>
          </geometry>
          <material>
            <script>
              <name>Gazebo/Black</name>
              <uri>file://media/materials/scripts/gazebo.material</uri>
            </script>
          </material>
        </visual>
        <visual name='base_link_fixed_joint_lump__face_link_visual_6'>
          <pose>0.098 0 0.059 0 1.5 0</pose>
          <geometry>
            <cylinder>
              <length>0.02</length>
              <radius>0.05</radius>
            </cylinder>
          </geometry>
          <material>
            <script>
              <name>Gazebo/Black</name>
              <uri>file://media/materials/scripts/gazebo.material</uri>
            </script>
          </material>
        </visual>
        <visual name='base_link_fixed_joint_lump__laser_frame_visual_7'>
          <pose>-0.104 0 0.202 0 -0 0</pose>
          <geometry>
            <cylinder>
              <length>0.04</length>
              <radius>0.05</radius>
            </cylinder>
          </geometry>
          <material>
            <script>
              <name>Gazebo/Black</name>
              <uri>file://media/materials/scripts/gazebo.material</uri>
            </script>
          </material>
        </visual>
        <visual name='base_link_fixed_joint_lump__laser_frame_visual_8'>
          <pose>-0.104 0 0.152 0 -0 0</pose>
          <geometry>
            <cylinder>
              <length>0.1</length>
              <radius>0.01</radius>
            </cylinder>
          </geometry>
          <material>
            <script>
              <name>Gazebo/Black</name>
              <uri>file://media/materials/scripts/gazebo.material</uri>
            </script>
          </material>
        </visual>
        <sensor name='camera' type='camera'>
          <visualize>1</visualize>
          <update_rate>10</update_rate>
          <camera>
            <horizontal_fov>1.089</horizontal_fov>
            <image>
              <format>R8G8B8</format>
              <width>640</width>
              <height>480</height>
            </image>
            <clip>
              <near>0.05</near>
              <far>8</far>
            </clip>
          </camera>
          <plugin name='camera_controller' filename='libgazebo_ros_camera.so'>
            <frame_name>camera_link_optical</frame_name>
          </plugin>
          <pose>0.05 0 0.171 0 -0 0</pose>
        </sensor>
        <sensor name='laser' type='ray'>
          <visualize>0</visualize>
          <update_rate>10</update_rate>
          <ray>
            <scan>
              <horizontal>
                <samples>360</samples>
                <min_angle>-3.14</min_angle>
                <max_angle>3.14</max_angle>
                <resolution>1</resolution>
              </horizontal>
              <vertical>
                <samples>1</samples>
                <min_angle>0</min_angle>
                <max_angle>0</max_angle>
              </vertical>
            </scan>
            <range>
              <min>0.3</min>
              <max>12</max>
            </range>
          </ray>
          <plugin name='laser_controller' filename='libgazebo_ros_ray_sensor.so'>
            <ros>
              <argument>~/out:=scan</argument>
            </ros>
            <output_type>sensor_msgs/LaserScan</output_type>
            <frame_name>laser_frame</frame_name>
          </plugin>
          <pose>-0.104 0 0.202 0 -0 0</pose>
        </sensor>
        <self_collide>0</self_collide>
        <enable_wind>0</enable_wind>
        <kinematic>0</kinematic>
      </link>
      <joint name='left_wheel_joint' type='revolute'>
        <pose relative_to='base_link'>0 0.1485 0 -1.5708 0 0</pose>
        <parent>base_link</parent>
        <child>left_wheel</child>
        <axis>
          <xyz>0 0 1</xyz>
          <limit>
            <lower>-1e+16</lower>
            <upper>1e+16</upper>
          </limit>
          <dynamics>
            <spring_reference>0</spring_reference>
            <spring_stiffness>0</spring_stiffness>
          </dynamics>
        </axis>
      </joint>
      <link name='left_wheel'>
        <pose relative_to='left_wheel_joint'>0 0 0 0 -0 0</pose>
        <inertial>
          <pose>0 0 0 0 -0 0</pose>
          <mass>0.05</mass>
          <inertia>
            <ixx>1.64292e-05</ixx>
            <ixy>0</ixy>
            <ixz>0</ixz>
            <iyy>1.64292e-05</iyy>
            <iyz>0</iyz>
            <izz>2.7225e-05</izz>
          </inertia>
        </inertial>
        <collision name='left_wheel_collision'>
          <pose>0 0 0 0 -0 0</pose>
          <geometry>
            <sphere>
              <radius>0.033</radius>
            </sphere>
          </geometry>
          <surface>
            <contact>
              <ode/>
            </contact>
            <friction>
              <ode/>
              <torsional>
                <ode/>
              </torsional>
            </friction>
            <bounce/>
          </surface>
          <max_contacts>10</max_contacts>
        </collision>
        <visual name='left_wheel_visual'>
          <pose>0 0 0 0 -0 0</pose>
          <geometry>
            <cylinder>
              <length>0.026</length>
              <radius>0.033</radius>
            </cylinder>
          </geometry>
          <material>
            <script>
              <name>Gazebo/Blue</name>
              <uri>file://media/materials/scripts/gazebo.material</uri>
            </script>
          </material>
        </visual>
        <self_collide>0</self_collide>
        <enable_wind>0</enable_wind>
        <kinematic>0</kinematic>
      </link>
      <joint name='right_wheel_joint' type='revolute'>
        <pose relative_to='base_link'>0 -0.1485 0 1.5708 -0 0</pose>
        <parent>base_link</parent>
        <child>right_wheel</child>
        <axis>
          <xyz>0 0 -1</xyz>
          <limit>
            <lower>-1e+16</lower>
            <upper>1e+16</upper>
          </limit>
          <dynamics>
            <spring_reference>0</spring_reference>
            <spring_stiffness>0</spring_stiffness>
          </dynamics>
        </axis>
      </joint>
      <link name='right_wheel'>
        <pose relative_to='right_wheel_joint'>0 0 0 0 -0 0</pose>
        <inertial>
          <pose>0 0 0 0 -0 0</pose>
          <mass>0.05</mass>
          <inertia>
            <ixx>1.64292e-05</ixx>
            <ixy>0</ixy>
            <ixz>0</ixz>
            <iyy>1.64292e-05</iyy>
            <iyz>0</iyz>
            <izz>2.7225e-05</izz>
          </inertia>
        </inertial>
        <collision name='right_wheel_collision'>
          <pose>0 0 0 0 -0 0</pose>
          <geometry>
            <sphere>
              <radius>0.033</radius>
            </sphere>
          </geometry>
          <surface>
            <contact>
              <ode/>
            </contact>
            <friction>
              <ode/>
              <torsional>
                <ode/>
              </torsional>
            </friction>
            <bounce/>
          </surface>
          <max_contacts>10</max_contacts>
        </collision>
        <visual name='right_wheel_visual'>
          <pose>0 0 0 0 -0 0</pose>
          <geometry>
            <cylinder>
              <length>0.026</length>
              <radius>0.033</radius>
            </cylinder>
          </geometry>
          <material>
            <script>
              <name>Gazebo/Blue</name>
              <uri>file://media/materials/scripts/gazebo.material</uri>
            </script>
          </material>
        </visual>
        <self_collide>0</self_collide>
        <enable_wind>0</enable_wind>
        <kinematic>0</kinematic>
      </link>
      <static>0</static>
      <plugin name='gazebo_ros2_control' filename='libgazebo_ros2_control.so'>
        <parameters>/home/pradeep/Desktop/car_files/articulated_ws/install/articubot_one/share/articubot_one/config/my_controllers.yaml</parameters>
        <parameters>/home/pradeep/Desktop/car_files/articulated_ws/install/articubot_one/share/articubot_one/config/gaz_ros2_ctl_use_sim.yaml</parameters>
      </plugin>
      <pose>0 0 0 0 -0 0</pose>
    </model>
    <model name='1'>
      <static>1</static>
      <link name='link'>
        <visual name='visual'>
          <geometry>
            <mesh>
              <uri>model://1/meshes/1.dae</uri>
              <scale>2 2 2</scale>
            </mesh>
          </geometry>
        </visual>
        <self_collide>0</self_collide>
        <enable_wind>0</enable_wind>
        <kinematic>0</kinematic>
      </link>
      <pose>2.66349 0.204664 0 0 -0 0</pose>
    </model>
    <state world_name='default'>
      <sim_time>55 9000000</sim_time>
      <real_time>56 145730150</real_time>
      <wall_time>1713110865 111414129</wall_time>
      <iterations>55009</iterations>
      <model name='1'>
        <pose>2.66349 0.204664 -0.218627 0 0 -3.10672</pose>
        <scale>1 1 1</scale>
        <link name='link'>
          <pose>2.66349 0.204664 -0.218627 0 0 -3.10672</pose>
          <velocity>0 0 0 0 -0 0</velocity>
          <acceleration>0 0 0 0 -0 0</acceleration>
          <wrench>0 0 0 0 -0 0</wrench>
        </link>
      </model>
      <model name='ground_plane'>
        <pose>0 0 0 0 -0 0</pose>
        <scale>1 1 1</scale>
        <link name='link'>
          <pose>0 0 0 0 -0 0</pose>
          <velocity>0 0 0 0 -0 0</velocity>
          <acceleration>0 0 0 0 -0 0</acceleration>
          <wrench>0 0 0 0 -0 0</wrench>
        </link>
      </model>
      <model name='my_bot'>
        <pose>-0.036999 4.4e-05 0.032997 1.6e-05 1.8e-05 0.001199</pose>
        <scale>1 1 1</scale>
        <link name='base_link'>
          <pose>-0.036999 4.4e-05 0.032997 1.6e-05 1.8e-05 0.001199</pose>
          <velocity>-0.000676 0.001274 1e-06 0.032507 3.6e-05 -0.005419</velocity>
          <acceleration>0.001929 -1.991 0.000599 2.18133 0.092573 1.69134</acceleration>
          <wrench>0.001177 -1.21451 0.000365 0 -0 0</wrench>
        </link>
        <link name='left_wheel'>
          <pose>-0.037177 0.148542 0.033 -1.57105 0.088423 0.001176</pose>
          <velocity>0.000107 0.000739 0.004889 -0.020573 0.003215 -0.005441</velocity>
          <acceleration>1.59062 2.01319 9.71665 2.51026 1.17593 -2.34749</acceleration>
          <wrench>0.079531 0.10066 0.485832 0 -0 0</wrench>
        </link>
        <link name='right_wheel'>
          <pose>-0.036821 -0.148453 0.032995 1.57103 0.090148 0.00122</pose>
          <velocity>-0.001453 0.000751 -0.004904 -0.02093 -1.9e-05 -0.005395</velocity>
          <acceleration>-1.58985 2.02386 -9.73064 -0.989283 0.017255 0.869479</acceleration>
          <wrench>-0.079493 0.101193 -0.486532 0 -0 0</wrench>
        </link>
      </model>
      <light name='sun'>
        <pose>0 0 10 0 -0 0</pose>
      </light>
    </state>
    <gui fullscreen='0'>
      <camera name='user_camera'>
        <pose>0.061022 1.50697 0.750312 -0 0.171643 -0.319806</pose>
        <view_controller>orbit</view_controller>
        <projection_type>perspective</projection_type>
      </camera>
    </gui>
  </world>
</sdf>
