<?xml version="1.0"?>
<robot name="superbot">

    <!-- Materials -->
    <material name="red">
        <color rgba="1.0 0.0 0.0 1.0"/>
    </material>
    <material name="green">
        <color rgba="0 0.6 0 1"/>
    </material>
    <material name="white">
        <color rgba="1 1 1 1"/>
    </material>

    <!-- Links -->
    <link name="base_footprint"/>

    <link name="base_link">
        <inertial>
            <origin xyz="0 0 0.1" rpy="0 0 0"/>
            <mass value="5.0"/>
            <inertia ixx="0.1" ixy="0.0" ixz="0.0" iyy="0.1" iyz="0.0" izz="0.1"/>
        </inertial>
        <visual>
            <geometry>
                <box size="0.6 0.4 0.2"/>
            </geometry>
            <origin xyz="0 0 0.1" rpy="0 0 0"/>
            <material name="green"/>
        </visual>
        <collision>
            <geometry>
                <box size="0.6 0.4 0.2"/>
            </geometry>
            <origin xyz="0 0 0.1" rpy="0 0 0"/>
        </collision>
    </link>

    <link name="lidar">
        <inertial>
            <origin xyz="0 0 0" rpy="0 0 0"/>
            <mass value="0.5"/>
            <inertia ixx="0.01" ixy="0.0" ixz="0.0" iyy="0.01" iyz="0.0" izz="0.01"/>
        </inertial>
        <visual>
            <geometry>
                <cylinder radius="0.1" length="0.05"/>
            </geometry>
            <origin xyz="0 0 0" rpy="0 0 0"/>
            <material name="red"/>
        </visual>
        <collision>
            <geometry>
                <cylinder radius="0.1" length="0.05"/>
            </geometry>
            <origin xyz="0 0 0" rpy="0 0 0"/>
        </collision>
    </link>

    <!-- Left Wheel -->
    <link name="left_wheel">
        <inertial>
            <origin xyz="0 0 0" rpy="0 0 0"/>
            <mass value="1.0"/>
            <inertia ixx="0.005" ixy="0.0" ixz="0.0" iyy="0.005" iyz="0.0" izz="0.005"/>
        </inertial>
        <visual>
            <geometry>
                <cylinder radius="0.1" length="0.05"/>
            </geometry>
            <origin xyz="0 0 0" rpy="0 0 0"/>
            <material name="white"/>
        </visual>
        <collision>
            <geometry>
                <cylinder radius="0.1" length="0.05"/>
            </geometry>
            <origin xyz="0 0 0" rpy="0 0 0"/>
        </collision>
    </link>

    <!-- Right Wheel -->
    <link name="right_wheel">
        <inertial>
            <origin xyz="0 0 0" rpy="0 0 0"/>
            <mass value="1.0"/>
            <inertia ixx="0.005" ixy="0.0" ixz="0.0" iyy="0.005" iyz="0.0" izz="0.005"/>
        </inertial>
        <visual>
            <geometry>
                <cylinder radius="0.1" length="0.05"/>
            </geometry>
            <origin xyz="0 0 0" rpy="0 0 0"/>
            <material name="white"/>
        </visual>
        <collision>
            <geometry>
                <cylinder radius="0.1" length="0.05"/>
            </geometry>
            <origin xyz="0 0 0" rpy="0 0 0"/>
        </collision>
    </link>

    <!-- Caster Wheel -->
    <link name="caster_wheel">
        <inertial>
            <origin xyz="0 0 0" rpy="0 0 0"/>
            <mass value="0.2"/>
            <inertia ixx="0.001" ixy="0.0" ixz="0.0" iyy="0.001" iyz="0.0" izz="0.001"/>
        </inertial>
        <visual>
            <geometry>
                <sphere radius="0.05"/>
            </geometry>
            <origin xyz="0 0 0" rpy="0 0 0"/>
            <material name="white"/>
        </visual>
        <collision>
            <geometry>
                <sphere radius="0.05"/>
            </geometry>
            <origin xyz="0 0 0" rpy="0 0 0"/>
        </collision>
    </link>

    <!-- Joints -->
    <joint name="base_joint" type="fixed">
        <parent link="base_footprint"/>
        <child link="base_link"/>
        <origin xyz="0 0 0.1" rpy="0 0 0"/>
    </joint>

    <joint name="base_lidar_joint" type="fixed">
        <parent link="base_link"/>
        <child link="lidar"/>
        <origin xyz="0 0 0.225" rpy="0 0 0"/>
    </joint>

    <joint name="base_left_wheel_joint" type="continuous">
        <parent link="base_link"/>
        <child link="left_wheel"/>
        <origin xyz="-0.3 0.225 0" rpy="0 0 0"/>
        <axis xyz="0 1 0"/>
    </joint>

    <joint name="base_right_wheel_joint" type="continuous">
        <parent link="base_link"/>
        <child link="right_wheel"/>
        <origin xyz="-0.3 -0.225 0" rpy="0 0 0"/>
        <axis xyz="0 1 0"/>
    </joint>

    <joint name="base_caster_wheel_joint" type="fixed">
        <parent link="base_link"/>
        <child link="caster_wheel"/>
        <origin xyz="0.2 0 -0.05" rpy="0 0 0"/>
    </joint>

    <!-- Plugins -->
    <plugin name="diff_drive_controller" filename="libgazebo_ros_diff_drive.so">
        <ros>
            <namespace>/</namespace>
            <remapping>cmd_vel:=/cmd_vel</remapping>
            <remapping>odom:=/odom</remapping>
        </ros>
        <update_rate>50</update_rate>
        <publish_odometry>true</publish_odometry>
        <publish_odometry_tf>true</publish_odometry_tf>
        <odometry_frame>odom</odometry_frame>
        <robot_base_frame>base_footprint</robot_base_frame>
        <wheel_separation>0.45</wheel_separation>
        <wheel_radius>0.1</wheel_radius>
        <left_joint>base_left_wheel_joint</left_joint>
        <right_joint>base_right_wheel_joint</right_joint>
    </plugin>

    <gazebo reference="lidar">
        <sensor name="lidar" type="ray">
            <always_on>true</always_on>
            <visualize>true</visualize>
            <update_rate>20</update_rate>
            <ray>
                <scan>
                    <horizontal>
                        <samples>360</samples>
                        <resolution>1.0</resolution>
                        <min_angle>-3.14159</min_angle>
                        <max_angle>3.14159</max_angle>
                    </horizontal>
                </scan>
                <range>
                    <min>0.3</min>
                    <max>15.0</max>
                    <resolution>0.015</resolution>
                </range>
            </ray>
            <plugin name="scan" filename="libgazebo_ros_ray_sensor.so">
                <ros>
                    <remapping>~/out:=scan</remapping>
                </ros>
                <output_type>sensor_msgs/LaserScan</output_type>
                <frame_name>lidar</frame_name>
            </plugin>
        </sensor>
    </gazebo>
    
</robot>
